Workbook
Name caracteristica_textura: [1]!t_caracteristica_camaron[caracteristica]
Name color_heces: [1]!t_colorheces[color_heces]
Name protocolo: [1]listas!$DP$2:$DP$3
Name rpm: [1]listas!$FH$2:$FH$10
Name SegmentaciónDeDatos_Fecha: #N/A
Name SegmentaciónDeDatos_Marca_Alimento: #N/A
Name SegmentaciónDeDatos_Psc: #N/A
Name si_no: [1]!t_sino[si_no]
Name unidad_medida: [1]listas!$DN$2:$DN$3

Sheet VALIDACIÓN 
A1: 46021 | Z1: NormalCalor | AA1: MinCalor | AR1: 400000 | AS1: 5000
A2: Psc | B2: Marca Alimento | C2: Ha | D2: Siembra | E2: Fecha | F2: Días | G2: %Diferencia Alimentación Actual&Teórica | H2: Kg/ semanal | I2: Bal Acumulado | J2: Fca | K2: Lbs/ha sin Raleo | L2: Lbs/ha+Raleo | M2: Raleo/total | N2: Gr/Raleo | O2: Raleo/lb/ha | P2: Kg/Ha Actual | Q2: Kg/ 100mil | R2: Dias alimentados | S2: Kg Alimento diario | T2: Kg/Ha Sugerido | U2: Kg Alimento Sugerido | V2: Kg Minimo | W2: Kg/Ha min | X2: Peso Actual | Y2: BW Actual | Z2: BW Sugerida | AA2: BW(min) | AB2: Biomasa Lb/Ha bajo sugerencia | AC2: Biomasa de camaron | AD2: Biomasa de camaron 2 | AE2: Biomasa Lb/Ha bajo reportado | AF2: Biomasa de Camaron bajo reportado | AG2: Biomasa/Ha Camaron Alimentación Actual | AH2: Biomasa de camaron alimentacion actual | AI2: Biomasa de camaron alimentacion 2 | AJ2: Animales Sembrados | AK2: Densidad/ha | AL2: Animales vivos reportados | AM2: Biomasa Lbs/Ha | AN2: Animales según alimentación sugerida | AO2: Animales según alimentación actual | AP2: Animales según tabla 2(Min) | AQ2: #AA | AR2: AnimalesAA | AS2: Kg/AA | AT2: #AR | AU2: Hp/AR | AV2: %Efi AR | AW2: Hp/Efi | AX2: Total hp/AR | AY2: Hp/ha | AZ2: Incremento actual | BA2: Incremento teorico | BB2: Sobrevivencia total en finca | BC2: CXMT ACTUAL | BD2: Sobrevivencia actual en agua | BE2: sobrevivencia actual por consumo | BF2: Observación
A3: 717 | B3: MAX AP | C3: 3.4 | D3: 46178 | E3: 46178 | F3: =Tabla14[[#This Row],[Fecha]]-Tabla14[[#This Row],[Siembra]] -> 0 | G3: =IFERROR((((Tabla14[[#This Row],[Kg Alimento diario ]]-Tabla14[[#This Row],[Kg Alimento Sugerido]])/(Tabla14[[#This Row],[Kg Alimento Sugerido]])*100)),"") -> -14.285714 | H3: 600 | I3: =IFERROR( IF(OFFSET(Tabla14[[#This Row],[Psc]],-1,0)=Tabla14[[#This Row],[Psc]], OFFSET(Tabla14[[#This Row],[Bal Acumulado]],-1,0)+Tabla14[[#This Row],[Kg/ semanal]], Tabla14[[#This Row],[Kg/ semanal]] ), Tabla14[[#This Row],[Kg/ semanal]] ) -> 600 | J3: =IFERROR(((Tabla14[[#This Row],[Bal Acumulado]]*2.2046/Tabla14[[#This Row],[Ha]])/L3),"") -> 1.6591896 | K3: =Tabla14[[#This Row],[Animales vivos reportados]]*Tabla14[[#This Row],[Peso Actual]]/454/Tabla14[[#This Row],[Ha]] -> 233.48018 | L3: =Tabla14[[#This Row],[Animales vivos reportados]]*Tabla14[[#This Row],[Peso Actual]]/454/Tabla14[[#This Row],[Ha]]+1 -> 234.48018 | O3: =Tabla14[[#This Row],[Raleo/total]]/Tabla14[[#This Row],[Ha]] -> 0 | P3: =IFERROR(Tabla14[[#This Row],[Kg Alimento diario ]]/Tabla14[[#This Row],[Ha]],"") -> 25.210084 | Q3: =IFERROR((Tabla14[[#This Row],[Kg Alimento diario ]])/(Tabla14[[#This Row],[Animales vivos reportados]]/100000),"") -> 11.891549 | R3: 7 | S3: =Tabla14[[#This Row],[Kg/ semanal]]/Tabla14[[#This Row],[Dias alimentados]] -> 85.714286 | T3: =Tabla14[[#This Row],[Kg Alimento Sugerido]]/Tabla14[[#This Row],[Ha]] -> 29.411765 | U3: 100 | V3: 80 | W3: =Tabla14[[#This Row],[Kg Minimo]]/Tabla14[[#This Row],[Ha]] -> 23.529412 | X3: 0.5 | Y3: =IFERROR(Tabla14[[#This Row],[Kg Alimento diario ]]/(Tabla14[[#This Row],[Peso Actual]]/1000*Tabla14[[#This Row],[Animales vivos reportados]]),"") -> 0.23783098 | Z3: =IFERROR(IF($Z$1="NormalCalor", VLOOKUP(Tabla14[[#This Row],[Peso Actual]], Tabla!$A$4:$C$76, 2, TRUE)/100, VLOOKUP(Tabla14[[#This Row],[Peso Actual]], Tabla!$A$4:$C$76, 3, TRUE)/100), "") -> 0.11 | AA3: =IFERROR(IF($AA$1="MinFrio",VLOOKUP(Tabla14[[#This Row],[Peso Actual]],Tabla!$F$3:$H$482,3,1),VLOOKUP(Tabla14[[#This Row],[Peso Actual]],Tabla!$F$3:$H$482,2,1)),"") -> 0.09634305 | AB3: =+Tabla14[[#This Row],[Biomasa de camaron ]]/Tabla14[[#This Row],[Ha]]*2.2 -> 588.23529 | AC3: =U3/Z3 -> 909.09091 | AD3: =V3/AA3 -> 830.36608 | AE3: =+Tabla14[[#This Row],[Biomasa de Camaron bajo reportado]]*2.2 -> 634.304 | AF3: =+(Tabla14[[#This Row],[Sobrevivencia total en finca]]/100)*Tabla14[[#This Row],[Animales vivos reportados]]*Tabla14[[#This Row],[Peso Actual]]/1000 -> 288.32 | AG3: =+Tabla14[[#This Row],[Biomasa de camaron alimentacion actual]]/Tabla14[[#This Row],[Ha]]*2.2 -> 504.20168 | AH3: =(Tabla14[[#This Row],[Kg Alimento diario ]]/Tabla14[[#This Row],[BW Sugerida]]) -> 779.22078 | AI3: =(Tabla14[[#This Row],[Kg Minimo]]/Tabla14[[#This Row],[BW(min)]]) -> 830.36608 | AJ3: =Tabla14[[#This Row],[Densidad/ha]]*Tabla14[[#This Row],[Ha]] -> 901000 | AK3: 265000 | AL3: =Tabla14[[#This Row],[Animales Sembrados]]*Tabla14[[#This Row],[Sobrevivencia total en finca]]/100 -> 720800 | AM3: =Tabla14[[#This Row],[Animales vivos reportados]]*Tabla14[[#This Row],[Peso Actual]]/454/Tabla14[[#This Row],[Ha]] -> 233.48018 | AN3: =IFERROR( (Tabla14[[#This Row],[Biomasa de camaron ]]*1000/Tabla14[[#This Row],[Peso Actual]]),"") -> 1818181.8 | AO3: =IFERROR(((Tabla14[[#This Row],[Biomasa de camaron alimentacion actual]]*1000)/Tabla14[[#This Row],[Peso Actual]]),"") -> 1558441.6 | AP3: =IFERROR( ( (Tabla14[[#This Row],[Biomasa de camaron alimentacion 2]]*1000)/Tabla14[[#This Row],[Peso Actual]]),"") -> 1660732.2 | AQ3: 5 | AR3: =IFERROR(Tabla14[[#This Row],[Animales vivos reportados]]/Tabla14[[#This Row],['#AA]],"") -> 144160 | AS3: =IFERROR(((Tabla14[[#This Row],[Lbs/ha sin Raleo]]*Tabla14[[#This Row],[Ha]])/Tabla14[[#This Row],['#AA]])/2.2046,"") -> 72.016021 | AT3: 14 | AU3: 16 | AV3: 0.6 | AW3: =Tabla14[[#This Row],[Hp/AR]]*Tabla14[[#This Row],[%Efi AR]] -> 9.6 | AX3: =Tabla14[[#This Row],[Hp/Efi]]*Tabla14[[#This Row],['#AR]] -> 134.4 | AY3: =Tabla14[[#This Row],[Total hp/AR]]/Tabla14[[#This Row],[Ha]] -> 39.529412 | BB3: 80 | BC3: =IFERROR(Tabla14[[#This Row],[Animales vivos reportados]]/Tabla14[[#This Row],[Ha]]/10000,"") -> 21.2 | BD3: =IFERROR((Tabla14[[#This Row],[CXMT ACTUAL]]*10000*Tabla14[[#This Row],[Ha]])/Tabla14[[#This Row],[Animales Sembrados]],"") -> 0.8 | BE3: =IFERROR( Tabla14[[#This Row],[Animales según alimentación actual]]/(Tabla14[[#This Row],[Densidad/ha]]*Tabla14[[#This Row],[Ha]]),"") -> 1.7296799
A4: 716 | B4: MAX AP | C4: 4.3 | D4: 46178 | E4: 46178 | F4: =Tabla14[[#This Row],[Fecha]]-Tabla14[[#This Row],[Siembra]] -> 0 | G4: =IFERROR((((Tabla14[[#This Row],[Kg Alimento diario ]]-Tabla14[[#This Row],[Kg Alimento Sugerido]])/(Tabla14[[#This Row],[Kg Alimento Sugerido]])*100)),"") -> 7.1428571 | H4: 1800 | I4: =IFERROR( IF(OFFSET(Tabla14[[#This Row],[Psc]],-1,0)=Tabla14[[#This Row],[Psc]], OFFSET(Tabla14[[#This Row],[Bal Acumulado]],-1,0)+Tabla14[[#This Row],[Kg/ semanal]], Tabla14[[#This Row],[Kg/ semanal]] ), Tabla14[[#This Row],[Kg/ semanal]] ) -> 1800 | J4: =IFERROR(((Tabla14[[#This Row],[Bal Acumulado]]*2.2046/Tabla14[[#This Row],[Ha]])/L4),"") -> 1.515242 | K4: =Tabla14[[#This Row],[Animales vivos reportados]]*Tabla14[[#This Row],[Peso Actual]]/454/Tabla14[[#This Row],[Ha]] -> 607.04846 | L4: =Tabla14[[#This Row],[Animales vivos reportados]]*Tabla14[[#This Row],[Peso Actual]]/454/Tabla14[[#This Row],[Ha]]+2 -> 609.04846 | O4: =Tabla14[[#This Row],[Raleo/total]]/Tabla14[[#This Row],[Ha]] -> 0 | P4: =IFERROR(Tabla14[[#This Row],[Kg Alimento diario ]]/Tabla14[[#This Row],[Ha]],"") -> 59.800664 | Q4: =IFERROR((Tabla14[[#This Row],[Kg Alimento diario ]])/(Tabla14[[#This Row],[Animales vivos reportados]]/100000),"") -> 28.207861 | R4: 7 | S4: =Tabla14[[#This Row],[Kg/ semanal]]/Tabla14[[#This Row],[Dias alimentados]] -> 257.14286 | T4: =Tabla14[[#This Row],[Kg Alimento Sugerido]]/Tabla14[[#This Row],[Ha]] -> 55.813953 | U4: 240 | V4: 215 | W4: =Tabla14[[#This Row],[Kg Minimo]]/Tabla14[[#This Row],[Ha]] -> 50 | X4: 1.3 | Y4: =IFERROR(Tabla14[[#This Row],[Kg Alimento diario ]]/(Tabla14[[#This Row],[Peso Actual]]/1000*Tabla14[[#This Row],[Animales vivos reportados]]),"") -> 0.21698354 | Z4: =IFERROR(IF($Z$1="NormalCalor", VLOOKUP(Tabla14[[#This Row],[Peso Actual]], Tabla!$A$4:$C$76, 2, TRUE)/100, VLOOKUP(Tabla14[[#This Row],[Peso Actual]], Tabla!$A$4:$C$76, 3, TRUE)/100), "") -> 0.1 | AA4: =IFERROR(IF($AA$1="MinFrio",VLOOKUP(Tabla14[[#This Row],[Peso Actual]],Tabla!$F$3:$H$482,3,1),VLOOKUP(Tabla14[[#This Row],[Peso Actual]],Tabla!$F$3:$H$482,2,1)),"") -> 0.084120945 | AB4: =+Tabla14[[#This Row],[Biomasa de camaron ]]/Tabla14[[#This Row],[Ha]]*2.2 -> 1227.907 | AC4: =U4/Z4 -> 2400 | AD4: =V4/AA4 -> 2555.8439 | AE4: =+Tabla14[[#This Row],[Biomasa de Camaron bajo reportado]]*2.2 -> 2085.7408 | AF4: =+(Tabla14[[#This Row],[Sobrevivencia total en finca]]/100)*Tabla14[[#This Row],[Animales vivos reportados]]*Tabla14[[#This Row],[Peso Actual]]/1000 -> 948.064 | AG4: =+Tabla14[[#This Row],[Biomasa de camaron alimentacion actual]]/Tabla14[[#This Row],[Ha]]*2.2 -> 1315.6146 | AH4: =(Tabla14[[#This Row],[Kg Alimento diario ]]/Tabla14[[#This Row],[BW Sugerida]]) -> 2571.4286 | AI4: =(Tabla14[[#This Row],[Kg Minimo]]/Tabla14[[#This Row],[BW(min)]]) -> 2555.8439 | AJ4: =Tabla14[[#This Row],[Densidad/ha]]*Tabla14[[#This Row],[Ha]] -> 1139500 | AK4: 265000 | AL4: =Tabla14[[#This Row],[Animales Sembrados]]*Tabla14[[#This Row],[Sobrevivencia total en finca]]/100 -> 911600 | AM4: =Tabla14[[#This Row],[Animales vivos reportados]]*Tabla14[[#This Row],[Peso Actual]]/454/Tabla14[[#This Row],[Ha]] -> 607.04846 | AN4: =IFERROR( (Tabla14[[#This Row],[Biomasa de camaron ]]*1000/Tabla14[[#This Row],[Peso Actual]]),"") -> 1846153.8 | AO4: =IFERROR(((Tabla14[[#This Row],[Biomasa de camaron alimentacion actual]]*1000)/Tabla14[[#This Row],[Peso Actual]]),"") -> 1978022 | AP4: =IFERROR( ( (Tabla14[[#This Row],[Biomasa de camaron alimentacion 2]]*1000)/Tabla14[[#This Row],[Peso Actual]]),"") -> 1966033.7 | AQ4: 5 | AR4: =IFERROR(Tabla14[[#This Row],[Animales vivos reportados]]/Tabla14[[#This Row],['#AA]],"") -> 182320 | AS4: =IFERROR(((Tabla14[[#This Row],[Lbs/ha sin Raleo]]*Tabla14[[#This Row],[Ha]])/Tabla14[[#This Row],['#AA]])/2.2046,"") -> 236.80562 | AT4: 14 | AU4: 16 | AV4: 0.6 | AW4: =Tabla14[[#This Row],[Hp/AR]]*Tabla14[[#This Row],[%Efi AR]] -> 9.6 | AX4: =Tabla14[[#This Row],[Hp/Efi]]*Tabla14[[#This Row],['#AR]] -> 134.4 | AY4: =Tabla14[[#This Row],[Total hp/AR]]/Tabla14[[#This Row],[Ha]] -> 31.255814 | AZ4: =IF(Tabla14[[#This Row],[Peso Actual]]>X3,Tabla14[[#This Row],[Peso Actual]]-X3,"") -> 0.8 | BB4: 80 | BC4: =IFERROR(Tabla14[[#This Row],[Animales vivos reportados]]/Tabla14[[#This Row],[Ha]]/10000,"") -> 21.2 | BD4: =IFERROR((Tabla14[[#This Row],[CXMT ACTUAL]]*10000*Tabla14[[#This Row],[Ha]])/Tabla14[[#This Row],[Animales Sembrados]],"") -> 0.8 | BE4: =IFERROR( Tabla14[[#This Row],[Animales según alimentación actual]]/(Tabla14[[#This Row],[Densidad/ha]]*Tabla14[[#This Row],[Ha]]),"") -> 1.7358683
A5: 714 | B5: MAX AP | C5: 3.156 | D5: 46182 | E5: 46178 | F5: =Tabla14[[#This Row],[Fecha]]-Tabla14[[#This Row],[Siembra]] -> -4 | G5: =IFERROR((((Tabla14[[#This Row],[Kg Alimento diario ]]-Tabla14[[#This Row],[Kg Alimento Sugerido]])/(Tabla14[[#This Row],[Kg Alimento Sugerido]])*100)),"") -> -16.666667 | H5: 3150 | I5: =IFERROR( IF(OFFSET(Tabla14[[#This Row],[Psc]],-1,0)=Tabla14[[#This Row],[Psc]], OFFSET(Tabla14[[#This Row],[Bal Acumulado]],-1,0)+Tabla14[[#This Row],[Kg/ semanal]], Tabla14[[#This Row],[Kg/ semanal]] ), Tabla14[[#This Row],[Kg/ semanal]] ) -> 3150 | J5: =IFERROR(((Tabla14[[#This Row],[Bal Acumulado]]*2.2046/Tabla14[[#This Row],[Ha]])/L5),"") -> 1.38594 | K5: =Tabla14[[#This Row],[Animales vivos reportados]]*Tabla14[[#This Row],[Peso Actual]]/454/Tabla14[[#This Row],[Ha]] -> 1587.6652 | L5: =Tabla14[[#This Row],[Animales vivos reportados]]*Tabla14[[#This Row],[Peso Actual]]/454/Tabla14[[#This Row],[Ha]]+O3 -> 1587.6652 | O5: =Tabla14[[#This Row],[Raleo/total]]/Tabla14[[#This Row],[Ha]] -> 0 | P5: =IFERROR(Tabla14[[#This Row],[Kg Alimento diario ]]/Tabla14[[#This Row],[Ha]],"") -> 142.58555 | Q5: =IFERROR((Tabla14[[#This Row],[Kg Alimento diario ]])/(Tabla14[[#This Row],[Animales vivos reportados]]/100000),"") -> 67.257336 | R5: 7 | S5: =Tabla14[[#This Row],[Kg/ semanal]]/Tabla14[[#This Row],[Dias alimentados]] -> 450 | T5: =Tabla14[[#This Row],[Kg Alimento Sugerido]]/Tabla14[[#This Row],[Ha]] -> 171.10266 | U5: 540 | V5: 415 | W5: =Tabla14[[#This Row],[Kg Minimo]]/Tabla14[[#This Row],[Ha]] -> 131.49556 | X5: 3.4 | Y5: =IFERROR(Tabla14[[#This Row],[Kg Alimento diario ]]/(Tabla14[[#This Row],[Peso Actual]]/1000*Tabla14[[#This Row],[Animales vivos reportados]]),"") -> 0.19781569 | Z5: =IFERROR(IF($Z$1="NormalCalor", VLOOKUP(Tabla14[[#This Row],[Peso Actual]], Tabla!$A$4:$C$76, 2, TRUE)/100, VLOOKUP(Tabla14[[#This Row],[Peso Actual]], Tabla!$A$4:$C$76, 3, TRUE)/100), "") -> 0.086 | AA5: =IFERROR(IF($AA$1="MinFrio",VLOOKUP(Tabla14[[#This Row],[Peso Actual]],Tabla!$F$3:$H$482,3,1),VLOOKUP(Tabla14[[#This Row],[Peso Actual]],Tabla!$F$3:$H$482,2,1)),"") -> 0.065450051 | AB5: =+Tabla14[[#This Row],[Biomasa de camaron ]]/Tabla14[[#This Row],[Ha]]*2.2 -> 4377.0448 | AC5: =U5/Z5 -> 6279.0698 | AD5: =V5/AA5 -> 6340.7132 | AE5: =+Tabla14[[#This Row],[Biomasa de Camaron bajo reportado]]*2.2 -> 4003.7268 | AF5: =+(Tabla14[[#This Row],[Sobrevivencia total en finca]]/100)*Tabla14[[#This Row],[Animales vivos reportados]]*Tabla14[[#This Row],[Peso Actual]]/1000 -> 1819.8758 | AG5: =+Tabla14[[#This Row],[Biomasa de camaron alimentacion actual]]/Tabla14[[#This Row],[Ha]]*2.2 -> 3647.5374 | AH5: =(Tabla14[[#This Row],[Kg Alimento diario ]]/Tabla14[[#This Row],[BW Sugerida]]) -> 5232.5581 | AI5: =(Tabla14[[#This Row],[Kg Minimo]]/Tabla14[[#This Row],[BW(min)]]) -> 6340.7132 | AJ5: =Tabla14[[#This Row],[Densidad/ha]]*Tabla14[[#This Row],[Ha]] -> 836340 | AK5: 265000 | AL5: =Tabla14[[#This Row],[Animales Sembrados]]*Tabla14[[#This Row],[Sobrevivencia total en finca]]/100 -> 669072 | AM5: =Tabla14[[#This Row],[Animales vivos reportados]]*Tabla14[[#This Row],[Peso Actual]]/454/Tabla14[[#This Row],[Ha]] -> 1587.6652 | AN5: =IFERROR( (Tabla14[[#This Row],[Biomasa de camaron ]]*1000/Tabla14[[#This Row],[Peso Actual]]),"") -> 1846785.2 | AO5: =IFERROR(((Tabla14[[#This Row],[Biomasa de camaron alimentacion actual]]*1000)/Tabla14[[#This Row],[Peso Actual]]),"") -> 1538987.7 | AP5: =IFERROR( ( (Tabla14[[#This Row],[Biomasa de camaron alimentacion 2]]*1000)/Tabla14[[#This Row],[Peso Actual]]),"") -> 1864915.6 | AQ5: 5 | AR5: =IFERROR(Tabla14[[#This Row],[Animales vivos reportados]]/Tabla14[[#This Row],['#AA]],"") -> 133814.4 | AS5: =IFERROR(((Tabla14[[#This Row],[Lbs/ha sin Raleo]]*Tabla14[[#This Row],[Ha]])/Tabla14[[#This Row],['#AA]])/2.2046,"") -> 454.56512 | AT5: 14 | AU5: 16 | AV5: 0.6 | AW5: =Tabla14[[#This Row],[Hp/AR]]*Tabla14[[#This Row],[%Efi AR]] -> 9.6 | AX5: =Tabla14[[#This Row],[Hp/Efi]]*Tabla14[[#This Row],['#AR]] -> 134.4 | AY5: =Tabla14[[#This Row],[Total hp/AR]]/Tabla14[[#This Row],[Ha]] -> 42.585551 | AZ5: =IF(Tabla14[[#This Row],[Peso Actual]]>X4,Tabla14[[#This Row],[Peso Actual]]-X4,"") -> 2.1 | BB5: 80 | BC5: =IFERROR(Tabla14[[#This Row],[Animales vivos reportados]]/Tabla14[[#This Row],[Ha]]/10000,"") -> 21.2 | BD5: =IFERROR((Tabla14[[#This Row],[CXMT ACTUAL]]*10000*Tabla14[[#This Row],[Ha]])/Tabla14[[#This Row],[Animales Sembrados]],"") -> 0.8 | BE5: =IFERROR( Tabla14[[#This Row],[Animales según alimentación actual]]/(Tabla14[[#This Row],[Densidad/ha]]*Tabla14[[#This Row],[Ha]]),"") -> 1.840146
A6: 816 | B6: KATAL 35% | D6: 46178 | E6: 46178 | F6: =Tabla14[[#This Row],[Fecha]]-Tabla14[[#This Row],[Siembra]] -> 0 | G6: =IFERROR((((Tabla14[[#This Row],[Kg Alimento diario ]]-Tabla14[[#This Row],[Kg Alimento Sugerido]])/(Tabla14[[#This Row],[Kg Alimento Sugerido]])*100)),"") | H6: 300 | I6: =IFERROR( IF(OFFSET(Tabla14[[#This Row],[Psc]],-1,0)=Tabla14[[#This Row],[Psc]], OFFSET(Tabla14[[#This Row],[Bal Acumulado]],-1,0)+Tabla14[[#This Row],[Kg/ semanal]], Tabla14[[#This Row],[Kg/ semanal]] ), Tabla14[[#This Row],[Kg/ semanal]] ) -> 300 | J6: =IFERROR(((Tabla14[[#This Row],[Bal Acumulado]]*2.2046/Tabla14[[#This Row],[Ha]])/L6),"") | K6: =Tabla14[[#This Row],[Animales vivos reportados]]*Tabla14[[#This Row],[Peso Actual]]/454/Tabla14[[#This Row],[Ha]] -> #DIV/0! | L6: =Tabla14[[#This Row],[Animales vivos reportados]]*Tabla14[[#This Row],[Peso Actual]]/454/Tabla14[[#This Row],[Ha]]+O4 -> #DIV/0! | O6: =Tabla14[[#This Row],[Raleo/total]]/Tabla14[[#This Row],[Ha]] -> #DIV/0! | P6: =IFERROR(Tabla14[[#This Row],[Kg Alimento diario ]]/Tabla14[[#This Row],[Ha]],"") | Q6: =IFERROR((Tabla14[[#This Row],[Kg Alimento diario ]])/(Tabla14[[#This Row],[Animales vivos reportados]]/100000),"") | R6: 7 | S6: =Tabla14[[#This Row],[Kg/ semanal]]/Tabla14[[#This Row],[Dias alimentados]] -> 42.857143 | T6: =Tabla14[[#This Row],[Kg Alimento Sugerido]]/Tabla14[[#This Row],[Ha]] -> #DIV/0! | W6: =Tabla14[[#This Row],[Kg Minimo]]/Tabla14[[#This Row],[Ha]] -> #DIV/0! | Y6: =IFERROR(Tabla14[[#This Row],[Kg Alimento diario ]]/(Tabla14[[#This Row],[Peso Actual]]/1000*Tabla14[[#This Row],[Animales vivos reportados]]),"") | Z6: =IFERROR(IF($Z$1="NormalCalor", VLOOKUP(Tabla14[[#This Row],[Peso Actual]], Tabla!$A$4:$C$76, 2, TRUE)/100, VLOOKUP(Tabla14[[#This Row],[Peso Actual]], Tabla!$A$4:$C$76, 3, TRUE)/100), "") | AA6: =IFERROR(IF($AA$1="MinFrio",VLOOKUP(Tabla14[[#This Row],[Peso Actual]],Tabla!$F$3:$H$482,3,1),VLOOKUP(Tabla14[[#This Row],[Peso Actual]],Tabla!$F$3:$H$482,2,1)),"") | AB6: =+Tabla14[[#This Row],[Biomasa de camaron ]]/Tabla14[[#This Row],[Ha]]*2.2 -> #VALUE! | AC6: =U6/Z6 -> #VALUE! | AD6: =V6/AA6 -> #VALUE! | AE6: =+Tabla14[[#This Row],[Biomasa de Camaron bajo reportado]]*2.2 -> 0 | AF6: =+(Tabla14[[#This Row],[Sobrevivencia total en finca]]/100)*Tabla14[[#This Row],[Animales vivos reportados]]*Tabla14[[#This Row],[Peso Actual]]/1000 -> 0 | AG6: =+Tabla14[[#This Row],[Biomasa de camaron alimentacion actual]]/Tabla14[[#This Row],[Ha]]*2.2 -> #VALUE! | AH6: =(Tabla14[[#This Row],[Kg Alimento diario ]]/Tabla14[[#This Row],[BW Sugerida]]) -> #VALUE! | AI6: =(Tabla14[[#This Row],[Kg Minimo]]/Tabla14[[#This Row],[BW(min)]]) -> #VALUE! | AJ6: =Tabla14[[#This Row],[Densidad/ha]]*Tabla14[[#This Row],[Ha]] -> 0 | AK6: 265000 | AL6: =Tabla14[[#This Row],[Animales Sembrados]]*Tabla14[[#This Row],[Sobrevivencia total en finca]]/100 -> 0 | AM6: =Tabla14[[#This Row],[Animales vivos reportados]]*Tabla14[[#This Row],[Peso Actual]]/454/Tabla14[[#This Row],[Ha]] -> #DIV/0! | AN6: =IFERROR( (Tabla14[[#This Row],[Biomasa de camaron ]]*1000/Tabla14[[#This Row],[Peso Actual]]),"") | AO6: =IFERROR(((Tabla14[[#This Row],[Biomasa de camaron alimentacion actual]]*1000)/Tabla14[[#This Row],[Peso Actual]]),"") | AP6: =IFERROR( ( (Tabla14[[#This Row],[Biomasa de camaron alimentacion 2]]*1000)/Tabla14[[#This Row],[Peso Actual]]),"") | AQ6: 5 | AR6: =IFERROR(Tabla14[[#This Row],[Animales vivos reportados]]/Tabla14[[#This Row],['#AA]],"") -> 0 | AS6: =IFERROR(((Tabla14[[#This Row],[Lbs/ha sin Raleo]]*Tabla14[[#This Row],[Ha]])/Tabla14[[#This Row],['#AA]])/2.2046,"") | AT6: 14 | AU6: 16 | AV6: 0.6 | AW6: =Tabla14[[#This Row],[Hp/AR]]*Tabla14[[#This Row],[%Efi AR]] -> 9.6 | AX6: =Tabla14[[#This Row],[Hp/Efi]]*Tabla14[[#This Row],['#AR]] -> 134.4 | AY6: =Tabla14[[#This Row],[Total hp/AR]]/Tabla14[[#This Row],[Ha]] -> #DIV/0! | AZ6: =IF(Tabla14[[#This Row],[Peso Actual]]>X5,Tabla14[[#This Row],[Peso Actual]]-X5,"") | BB6: 80 | BC6: =IFERROR(Tabla14[[#This Row],[Animales vivos reportados]]/Tabla14[[#This Row],[Ha]]/10000,"") | BD6: =IFERROR((Tabla14[[#This Row],[CXMT ACTUAL]]*10000*Tabla14[[#This Row],[Ha]])/Tabla14[[#This Row],[Animales Sembrados]],"") | BE6: =IFERROR( Tabla14[[#This Row],[Animales según alimentación actual]]/(Tabla14[[#This Row],[Densidad/ha]]*Tabla14[[#This Row],[Ha]]),"")
A7: 817 | B7: KATAL 35% | D7: 46178 | E7: 46178 | F7: =Tabla14[[#This Row],[Fecha]]-Tabla14[[#This Row],[Siembra]] -> 0 | G7: =IFERROR((((Tabla14[[#This Row],[Kg Alimento diario ]]-Tabla14[[#This Row],[Kg Alimento Sugerido]])/(Tabla14[[#This Row],[Kg Alimento Sugerido]])*100)),"") | H7: 45 | I7: =IFERROR( IF(OFFSET(Tabla14[[#This Row],[Psc]],-1,0)=Tabla14[[#This Row],[Psc]], OFFSET(Tabla14[[#This Row],[Bal Acumulado]],-1,0)+Tabla14[[#This Row],[Kg/ semanal]], Tabla14[[#This Row],[Kg/ semanal]] ), Tabla14[[#This Row],[Kg/ semanal]] ) -> 45 | J7: =IFERROR(((Tabla14[[#This Row],[Bal Acumulado]]*2.2046/Tabla14[[#This Row],[Ha]])/L7),"") | K7: =Tabla14[[#This Row],[Animales vivos reportados]]*Tabla14[[#This Row],[Peso Actual]]/454/Tabla14[[#This Row],[Ha]] -> #DIV/0! | L7: =Tabla14[[#This Row],[Animales vivos reportados]]*Tabla14[[#This Row],[Peso Actual]]/454/Tabla14[[#This Row],[Ha]]+O5 -> #DIV/0! | O7: =Tabla14[[#This Row],[Raleo/total]]/Tabla14[[#This Row],[Ha]] -> #DIV/0! | P7: =IFERROR(Tabla14[[#This Row],[Kg Alimento diario ]]/Tabla14[[#This Row],[Ha]],"") | Q7: =IFERROR((Tabla14[[#This Row],[Kg Alimento diario ]])/(Tabla14[[#This Row],[Animales vivos reportados]]/100000),"") | R7: 7 | S7: =Tabla14[[#This Row],[Kg/ semanal]]/Tabla14[[#This Row],[Dias alimentados]] -> 6.4285714 | T7: =Tabla14[[#This Row],[Kg Alimento Sugerido]]/Tabla14[[#This Row],[Ha]] -> #DIV/0! | V7: 1800 | W7: =Tabla14[[#This Row],[Kg Minimo]]/Tabla14[[#This Row],[Ha]] -> #DIV/0! | Y7: =IFERROR(Tabla14[[#This Row],[Kg Alimento diario ]]/(Tabla14[[#This Row],[Peso Actual]]/1000*Tabla14[[#This Row],[Animales vivos reportados]]),"") | Z7: =IFERROR(IF($Z$1="NormalCalor", VLOOKUP(Tabla14[[#This Row],[Peso Actual]], Tabla!$A$4:$C$76, 2, TRUE)/100, VLOOKUP(Tabla14[[#This Row],[Peso Actual]], Tabla!$A$4:$C$76, 3, TRUE)/100), "") | AA7: =IFERROR(IF($AA$1="MinFrio",VLOOKUP(Tabla14[[#This Row],[Peso Actual]],Tabla!$F$3:$H$482,3,1),VLOOKUP(Tabla14[[#This Row],[Peso Actual]],Tabla!$F$3:$H$482,2,1)),"") | AB7: =+Tabla14[[#This Row],[Biomasa de camaron ]]/Tabla14[[#This Row],[Ha]]*2.2 -> #VALUE! | AC7: =U7/Z7 -> #VALUE! | AD7: =V7/AA7 -> #VALUE! | AE7: =+Tabla14[[#This Row],[Biomasa de Camaron bajo reportado]]*2.2 -> 0 | AF7: =+(Tabla14[[#This Row],[Sobrevivencia total en finca]]/100)*Tabla14[[#This Row],[Animales vivos reportados]]*Tabla14[[#This Row],[Peso Actual]]/1000 -> 0 | AG7: =+Tabla14[[#This Row],[Biomasa de camaron alimentacion actual]]/Tabla14[[#This Row],[Ha]]*2.2 -> #VALUE! | AH7: =(Tabla14[[#This Row],[Kg Alimento diario ]]/Tabla14[[#This Row],[BW Sugerida]]) -> #VALUE! | AI7: =(Tabla14[[#This Row],[Kg Minimo]]/Tabla14[[#This Row],[BW(min)]]) -> #VALUE! | AJ7: =Tabla14[[#This Row],[Densidad/ha]]*Tabla14[[#This Row],[Ha]] -> 0 | AK7: 265000 | AL7: =Tabla14[[#This Row],[Animales Sembrados]]*Tabla14[[#This Row],[Sobrevivencia total en finca]]/100 -> 0 | AM7: =Tabla14[[#This Row],[Animales vivos reportados]]*Tabla14[[#This Row],[Peso Actual]]/454/Tabla14[[#This Row],[Ha]] -> #DIV/0! | AN7: =IFERROR( (Tabla14[[#This Row],[Biomasa de camaron ]]*1000/Tabla14[[#This Row],[Peso Actual]]),"") | AO7: =IFERROR(((Tabla14[[#This Row],[Biomasa de camaron alimentacion actual]]*1000)/Tabla14[[#This Row],[Peso Actual]]),"") | AP7: =IFERROR( ( (Tabla14[[#This Row],[Biomasa de camaron alimentacion 2]]*1000)/Tabla14[[#This Row],[Peso Actual]]),"") | AQ7: 5 | AR7: =IFERROR(Tabla14[[#This Row],[Animales vivos reportados]]/Tabla14[[#This Row],['#AA]],"") -> 0 | AS7: =IFERROR(((Tabla14[[#This Row],[Lbs/ha sin Raleo]]*Tabla14[[#This Row],[Ha]])/Tabla14[[#This Row],['#AA]])/2.2046,"") | AT7: 14 | AU7: 16 | AV7: 0.6 | AW7: =Tabla14[[#This Row],[Hp/AR]]*Tabla14[[#This Row],[%Efi AR]] -> 9.6 | AX7: =Tabla14[[#This Row],[Hp/Efi]]*Tabla14[[#This Row],['#AR]] -> 134.4 | AY7: =Tabla14[[#This Row],[Total hp/AR]]/Tabla14[[#This Row],[Ha]] -> #DIV/0! | AZ7: =IF(Tabla14[[#This Row],[Peso Actual]]>X6,Tabla14[[#This Row],[Peso Actual]]-X6,"") | BB7: 80 | BC7: =IFERROR(Tabla14[[#This Row],[Animales vivos reportados]]/Tabla14[[#This Row],[Ha]]/10000,"") | BD7: =IFERROR((Tabla14[[#This Row],[CXMT ACTUAL]]*10000*Tabla14[[#This Row],[Ha]])/Tabla14[[#This Row],[Animales Sembrados]],"") | BE7: =IFERROR( Tabla14[[#This Row],[Animales según alimentación actual]]/(Tabla14[[#This Row],[Densidad/ha]]*Tabla14[[#This Row],[Ha]]),"")
A8: 812 | B8: MAX AP | C8: 4.021 | D8: 46166 | E8: 46178 | F8: =Tabla14[[#This Row],[Fecha]]-Tabla14[[#This Row],[Siembra]] -> 12 | G8: =IFERROR((((Tabla14[[#This Row],[Kg Alimento diario ]]-Tabla14[[#This Row],[Kg Alimento Sugerido]])/(Tabla14[[#This Row],[Kg Alimento Sugerido]])*100)),"") | H8: 6 | I8: =IFERROR( IF(OFFSET(Tabla14[[#This Row],[Psc]],-1,0)=Tabla14[[#This Row],[Psc]], OFFSET(Tabla14[[#This Row],[Bal Acumulado]],-1,0)+Tabla14[[#This Row],[Kg/ semanal]], Tabla14[[#This Row],[Kg/ semanal]] ), Tabla14[[#This Row],[Kg/ semanal]] ) -> 6 | J8: =IFERROR(((Tabla14[[#This Row],[Bal Acumulado]]*2.2046/Tabla14[[#This Row],[Ha]])/L8),"") | K8: =Tabla14[[#This Row],[Animales vivos reportados]]*Tabla14[[#This Row],[Peso Actual]]/454/Tabla14[[#This Row],[Ha]] -> 0 | L8: =Tabla14[[#This Row],[Animales vivos reportados]]*Tabla14[[#This Row],[Peso Actual]]/454/Tabla14[[#This Row],[Ha]]+O6 -> #DIV/0! | O8: =Tabla14[[#This Row],[Raleo/total]]/Tabla14[[#This Row],[Ha]] -> 0 | P8: =IFERROR(Tabla14[[#This Row],[Kg Alimento diario ]]/Tabla14[[#This Row],[Ha]],"") -> 0.21316659 | Q8: =IFERROR((Tabla14[[#This Row],[Kg Alimento diario ]])/(Tabla14[[#This Row],[Animales vivos reportados]]/100000),"") -> 0.10055028 | R8: 7 | S8: =Tabla14[[#This Row],[Kg/ semanal]]/Tabla14[[#This Row],[Dias alimentados]] -> 0.85714286 | T8: =Tabla14[[#This Row],[Kg Alimento Sugerido]]/Tabla14[[#This Row],[Ha]] -> 0 | W8: =Tabla14[[#This Row],[Kg Minimo]]/Tabla14[[#This Row],[Ha]] -> 0 | Y8: =IFERROR(Tabla14[[#This Row],[Kg Alimento diario ]]/(Tabla14[[#This Row],[Peso Actual]]/1000*Tabla14[[#This Row],[Animales vivos reportados]]),"") | Z8: =IFERROR(IF($Z$1="NormalCalor", VLOOKUP(Tabla14[[#This Row],[Peso Actual]], Tabla!$A$4:$C$76, 2, TRUE)/100, VLOOKUP(Tabla14[[#This Row],[Peso Actual]], Tabla!$A$4:$C$76, 3, TRUE)/100), "") | AA8: =IFERROR(IF($AA$1="MinFrio",VLOOKUP(Tabla14[[#This Row],[Peso Actual]],Tabla!$F$3:$H$482,3,1),VLOOKUP(Tabla14[[#This Row],[Peso Actual]],Tabla!$F$3:$H$482,2,1)),"") | AB8: =+Tabla14[[#This Row],[Biomasa de camaron ]]/Tabla14[[#This Row],[Ha]]*2.2 -> #VALUE! | AC8: =U8/Z8 -> #VALUE! | AD8: =V8/AA8 -> #VALUE! | AE8: =+Tabla14[[#This Row],[Biomasa de Camaron bajo reportado]]*2.2 -> 0 | AF8: =+(Tabla14[[#This Row],[Sobrevivencia total en finca]]/100)*Tabla14[[#This Row],[Animales vivos reportados]]*Tabla14[[#This Row],[Peso Actual]]/1000 -> 0 | AG8: =+Tabla14[[#This Row],[Biomasa de camaron alimentacion actual]]/Tabla14[[#This Row],[Ha]]*2.2 -> #VALUE! | AH8: =(Tabla14[[#This Row],[Kg Alimento diario ]]/Tabla14[[#This Row],[BW Sugerida]]) -> #VALUE! | AI8: =(Tabla14[[#This Row],[Kg Minimo]]/Tabla14[[#This Row],[BW(min)]]) -> #VALUE! | AJ8: =Tabla14[[#This Row],[Densidad/ha]]*Tabla14[[#This Row],[Ha]] -> 1065565 | AK8: 265000 | AL8: =Tabla14[[#This Row],[Animales Sembrados]]*Tabla14[[#This Row],[Sobrevivencia total en finca]]/100 -> 852452 | AM8: =Tabla14[[#This Row],[Animales vivos reportados]]*Tabla14[[#This Row],[Peso Actual]]/454/Tabla14[[#This Row],[Ha]] -> 0 | AN8: =IFERROR( (Tabla14[[#This Row],[Biomasa de camaron ]]*1000/Tabla14[[#This Row],[Peso Actual]]),"") | AO8: =IFERROR(((Tabla14[[#This Row],[Biomasa de camaron alimentacion actual]]*1000)/Tabla14[[#This Row],[Peso Actual]]),"") | AP8: =IFERROR( ( (Tabla14[[#This Row],[Biomasa de camaron alimentacion 2]]*1000)/Tabla14[[#This Row],[Peso Actual]]),"") | AR8: =IFERROR(Tabla14[[#This Row],[Animales vivos reportados]]/Tabla14[[#This Row],['#AA]],"") | AS8: =IFERROR(((Tabla14[[#This Row],[Lbs/ha sin Raleo]]*Tabla14[[#This Row],[Ha]])/Tabla14[[#This Row],['#AA]])/2.2046,"") | AT8: 14 | AU8: 16 | AV8: 0.6 | AW8: =Tabla14[[#This Row],[Hp/AR]]*Tabla14[[#This Row],[%Efi AR]] -> 9.6 | AX8: =Tabla14[[#This Row],[Hp/Efi]]*Tabla14[[#This Row],['#AR]] -> 134.4 | AY8: =Tabla14[[#This Row],[Total hp/AR]]/Tabla14[[#This Row],[Ha]] -> 33.424521 | AZ8: =IF(Tabla14[[#This Row],[Peso Actual]]>X7,Tabla14[[#This Row],[Peso Actual]]-X7,"") | BB8: 80 | BC8: =IFERROR(Tabla14[[#This Row],[Animales vivos reportados]]/Tabla14[[#This Row],[Ha]]/10000,"") -> 21.2 | BD8: =IFERROR((Tabla14[[#This Row],[CXMT ACTUAL]]*10000*Tabla14[[#This Row],[Ha]])/Tabla14[[#This Row],[Animales Sembrados]],"") -> 0.8 | BE8: =IFERROR( Tabla14[[#This Row],[Animales según alimentación actual]]/(Tabla14[[#This Row],[Densidad/ha]]*Tabla14[[#This Row],[Ha]]),"")
A9: 813 | B9: MAX AP | C9: 3.147 | D9: 46166 | E9: 46178 | F9: =Tabla14[[#This Row],[Fecha]]-Tabla14[[#This Row],[Siembra]] -> 12 | G9: =IFERROR((((Tabla14[[#This Row],[Kg Alimento diario ]]-Tabla14[[#This Row],[Kg Alimento Sugerido]])/(Tabla14[[#This Row],[Kg Alimento Sugerido]])*100)),"") | H9: 77 | I9: =IFERROR( IF(OFFSET(Tabla14[[#This Row],[Psc]],-1,0)=Tabla14[[#This Row],[Psc]], OFFSET(Tabla14[[#This Row],[Bal Acumulado]],-1,0)+Tabla14[[#This Row],[Kg/ semanal]], Tabla14[[#This Row],[Kg/ semanal]] ), Tabla14[[#This Row],[Kg/ semanal]] ) -> 77 | J9: =IFERROR(((Tabla14[[#This Row],[Bal Acumulado]]*2.2046/Tabla14[[#This Row],[Ha]])/L9),"") | K9: =Tabla14[[#This Row],[Animales vivos reportados]]*Tabla14[[#This Row],[Peso Actual]]/454/Tabla14[[#This Row],[Ha]] -> 0 | L9: =Tabla14[[#This Row],[Animales vivos reportados]]*Tabla14[[#This Row],[Peso Actual]]/454/Tabla14[[#This Row],[Ha]]+O7 -> #DIV/0! | O9: =Tabla14[[#This Row],[Raleo/total]]/Tabla14[[#This Row],[Ha]] -> 0 | P9: =IFERROR(Tabla14[[#This Row],[Kg Alimento diario ]]/Tabla14[[#This Row],[Ha]],"") -> 3.4953924 | Q9: =IFERROR((Tabla14[[#This Row],[Kg Alimento diario ]])/(Tabla14[[#This Row],[Animales vivos reportados]]/100000),"") -> 1.64877 | R9: 7 | S9: =Tabla14[[#This Row],[Kg/ semanal]]/Tabla14[[#This Row],[Dias alimentados]] -> 11 | T9: =Tabla14[[#This Row],[Kg Alimento Sugerido]]/Tabla14[[#This Row],[Ha]] -> 0 | W9: =Tabla14[[#This Row],[Kg Minimo]]/Tabla14[[#This Row],[Ha]] -> 0 | Y9: =IFERROR(Tabla14[[#This Row],[Kg Alimento diario ]]/(Tabla14[[#This Row],[Peso Actual]]/1000*Tabla14[[#This Row],[Animales vivos reportados]]),"") | Z9: =IFERROR(IF($Z$1="NormalCalor", VLOOKUP(Tabla14[[#This Row],[Peso Actual]], Tabla!$A$4:$C$76, 2, TRUE)/100, VLOOKUP(Tabla14[[#This Row],[Peso Actual]], Tabla!$A$4:$C$76, 3, TRUE)/100), "") | AA9: =IFERROR(IF($AA$1="MinFrio",VLOOKUP(Tabla14[[#This Row],[Peso Actual]],Tabla!$F$3:$H$482,3,1),VLOOKUP(Tabla14[[#This Row],[Peso Actual]],Tabla!$F$3:$H$482,2,1)),"") | AB9: =+Tabla14[[#This Row],[Biomasa de camaron ]]/Tabla14[[#This Row],[Ha]]*2.2 -> #VALUE! | AC9: =U9/Z9 -> #VALUE! | AD9: =V9/AA9 -> #VALUE! | AE9: =+Tabla14[[#This Row],[Biomasa de Camaron bajo reportado]]*2.2 -> 0 | AF9: =+(Tabla14[[#This Row],[Sobrevivencia total en finca]]/100)*Tabla14[[#This Row],[Animales vivos reportados]]*Tabla14[[#This Row],[Peso Actual]]/1000 -> 0 | AG9: =+Tabla14[[#This Row],[Biomasa de camaron alimentacion actual]]/Tabla14[[#This Row],[Ha]]*2.2 -> #VALUE! | AH9: =(Tabla14[[#This Row],[Kg Alimento diario ]]/Tabla14[[#This Row],[BW Sugerida]]) -> #VALUE! | AI9: =(Tabla14[[#This Row],[Kg Minimo]]/Tabla14[[#This Row],[BW(min)]]) -> #VALUE! | AJ9: =Tabla14[[#This Row],[Densidad/ha]]*Tabla14[[#This Row],[Ha]] -> 833955 | AK9: 265000 | AL9: =Tabla14[[#This Row],[Animales Sembrados]]*Tabla14[[#This Row],[Sobrevivencia total en finca]]/100 -> 667164 | AM9: =Tabla14[[#This Row],[Animales vivos reportados]]*Tabla14[[#This Row],[Peso Actual]]/454/Tabla14[[#This Row],[Ha]] -> 0 | AN9: =IFERROR( (Tabla14[[#This Row],[Biomasa de camaron ]]*1000/Tabla14[[#This Row],[Peso Actual]]),"") | AO9: =IFERROR(((Tabla14[[#This Row],[Biomasa de camaron alimentacion actual]]*1000)/Tabla14[[#This Row],[Peso Actual]]),"") | AP9: =IFERROR( ( (Tabla14[[#This Row],[Biomasa de camaron alimentacion 2]]*1000)/Tabla14[[#This Row],[Peso Actual]]),"") | AR9: =IFERROR(Tabla14[[#This Row],[Animales vivos reportados]]/Tabla14[[#This Row],['#AA]],"") | AS9: =IFERROR(((Tabla14[[#This Row],[Lbs/ha sin Raleo]]*Tabla14[[#This Row],[Ha]])/Tabla14[[#This Row],['#AA]])/2.2046,"") | AT9: 14 | AU9: 16 | AV9: 0.6 | AW9: =Tabla14[[#This Row],[Hp/AR]]*Tabla14[[#This Row],[%Efi AR]] -> 9.6 | AX9: =Tabla14[[#This Row],[Hp/Efi]]*Tabla14[[#This Row],['#AR]] -> 134.4 | AY9: =Tabla14[[#This Row],[Total hp/AR]]/Tabla14[[#This Row],[Ha]] -> 42.70734 | AZ9: =IF(Tabla14[[#This Row],[Peso Actual]]>X8,Tabla14[[#This Row],[Peso Actual]]-X8,"") | BB9: 80 | BC9: =IFERROR(Tabla14[[#This Row],[Animales vivos reportados]]/Tabla14[[#This Row],[Ha]]/10000,"") -> 21.2 | BD9: =IFERROR((Tabla14[[#This Row],[CXMT ACTUAL]]*10000*Tabla14[[#This Row],[Ha]])/Tabla14[[#This Row],[Animales Sembrados]],"") -> 0.8 | BE9: =IFERROR( Tabla14[[#This Row],[Animales según alimentación actual]]/(Tabla14[[#This Row],[Densidad/ha]]*Tabla14[[#This Row],[Ha]]),"")
A10: 811 | B10: KATAL 35% | E10: 46178 | F10: =Tabla14[[#This Row],[Fecha]]-Tabla14[[#This Row],[Siembra]] -> 46178 | G10: =IFERROR((((Tabla14[[#This Row],[Kg Alimento diario ]]-Tabla14[[#This Row],[Kg Alimento Sugerido]])/(Tabla14[[#This Row],[Kg Alimento Sugerido]])*100)),"") | H10: 88 | I10: =IFERROR( IF(OFFSET(Tabla14[[#This Row],[Psc]],-1,0)=Tabla14[[#This Row],[Psc]], OFFSET(Tabla14[[#This Row],[Bal Acumulado]],-1,0)+Tabla14[[#This Row],[Kg/ semanal]], Tabla14[[#This Row],[Kg/ semanal]] ), Tabla14[[#This Row],[Kg/ semanal]] ) -> 88 | J10: =IFERROR(((Tabla14[[#This Row],[Bal Acumulado]]*2.2046/Tabla14[[#This Row],[Ha]])/L10),"") | K10: =Tabla14[[#This Row],[Animales vivos reportados]]*Tabla14[[#This Row],[Peso Actual]]/454/Tabla14[[#This Row],[Ha]] -> #DIV/0! | L10: =Tabla14[[#This Row],[Animales vivos reportados]]*Tabla14[[#This Row],[Peso Actual]]/454/Tabla14[[#This Row],[Ha]]+O8 -> #DIV/0! | M10: 0 | N10: 0 | O10: 0 | P10: =IFERROR(Tabla14[[#This Row],[Kg Alimento diario ]]/Tabla14[[#This Row],[Ha]],"") | Q10: =IFERROR((Tabla14[[#This Row],[Kg Alimento diario ]])/(Tabla14[[#This Row],[Animales vivos reportados]]/100000),"") | R10: 7 | S10: =Tabla14[[#This Row],[Kg/ semanal]]/Tabla14[[#This Row],[Dias alimentados]] -> 12.571429 | T10: =Tabla14[[#This Row],[Kg Alimento Sugerido]]/Tabla14[[#This Row],[Ha]] -> #DIV/0! | W10: =Tabla14[[#This Row],[Kg Minimo]]/Tabla14[[#This Row],[Ha]] -> #DIV/0! | Y10: =IFERROR(Tabla14[[#This Row],[Kg Alimento diario ]]/(Tabla14[[#This Row],[Peso Actual]]/1000*Tabla14[[#This Row],[Animales vivos reportados]]),"") | Z10: =IFERROR(IF($Z$1="NormalCalor", VLOOKUP(Tabla14[[#This Row],[Peso Actual]], Tabla!$A$4:$C$76, 2, TRUE)/100, VLOOKUP(Tabla14[[#This Row],[Peso Actual]], Tabla!$A$4:$C$76, 3, TRUE)/100), "") | AA10: =IFERROR(IF($AA$1="MinFrio",VLOOKUP(Tabla14[[#This Row],[Peso Actual]],Tabla!$F$3:$H$482,3,1),VLOOKUP(Tabla14[[#This Row],[Peso Actual]],Tabla!$F$3:$H$482,2,1)),"") | AB10: =+Tabla14[[#This Row],[Biomasa de camaron ]]/Tabla14[[#This Row],[Ha]]*2.2 -> #VALUE! | AC10: =U10/Z10 -> #VALUE! | AD10: =V10/AA10 -> #VALUE! | AE10: =+Tabla14[[#This Row],[Biomasa de Camaron bajo reportado]]*2.2 -> 0 | AF10: =+(Tabla14[[#This Row],[Sobrevivencia total en finca]]/100)*Tabla14[[#This Row],[Animales vivos reportados]]*Tabla14[[#This Row],[Peso Actual]]/1000 -> 0 | AG10: =+Tabla14[[#This Row],[Biomasa de camaron alimentacion actual]]/Tabla14[[#This Row],[Ha]]*2.2 -> #VALUE! | AH10: =(Tabla14[[#This Row],[Kg Alimento diario ]]/Tabla14[[#This Row],[BW Sugerida]]) -> #VALUE! | AI10: =(Tabla14[[#This Row],[Kg Minimo]]/Tabla14[[#This Row],[BW(min)]]) -> #VALUE! | AJ10: =Tabla14[[#This Row],[Densidad/ha]]*Tabla14[[#This Row],[Ha]] -> 0 | AK10: 265000 | AL10: =Tabla14[[#This Row],[Animales Sembrados]]*Tabla14[[#This Row],[Sobrevivencia total en finca]]/100 -> 0 | AM10: =Tabla14[[#This Row],[Animales vivos reportados]]*Tabla14[[#This Row],[Peso Actual]]/454/Tabla14[[#This Row],[Ha]] -> #DIV/0! | AN10: =IFERROR( (Tabla14[[#This Row],[Biomasa de camaron ]]*1000/Tabla14[[#This Row],[Peso Actual]]),"") | AO10: =IFERROR(((Tabla14[[#This Row],[Biomasa de camaron alimentacion actual]]*1000)/Tabla14[[#This Row],[Peso Actual]]),"") | AP10: =IFERROR( ( (Tabla14[[#This Row],[Biomasa de camaron alimentacion 2]]*1000)/Tabla14[[#This Row],[Peso Actual]]),"") | AR10: =IFERROR(Tabla14[[#This Row],[Animales vivos reportados]]/Tabla14[[#This Row],['#AA]],"") | AS10: =IFERROR(((Tabla14[[#This Row],[Lbs/ha sin Raleo]]*Tabla14[[#This Row],[Ha]])/Tabla14[[#This Row],['#AA]])/2.2046,"") | AT10: 14 | AU10: 16 | AV10: 0.6 | AW10: =Tabla14[[#This Row],[Hp/AR]]*Tabla14[[#This Row],[%Efi AR]] -> 9.6 | AX10: =Tabla14[[#This Row],[Hp/Efi]]*Tabla14[[#This Row],['#AR]] -> 134.4 | AY10: =Tabla14[[#This Row],[Total hp/AR]]/Tabla14[[#This Row],[Ha]] -> #DIV/0! | AZ10: =IF(Tabla14[[#This Row],[Peso Actual]]>X9,Tabla14[[#This Row],[Peso Actual]]-X9,"") | BB10: 80 | BC10: =IFERROR(Tabla14[[#This Row],[Animales vivos reportados]]/Tabla14[[#This Row],[Ha]]/10000,"") | BD10: =IFERROR((Tabla14[[#This Row],[CXMT ACTUAL]]*10000*Tabla14[[#This Row],[Ha]])/Tabla14[[#This Row],[Animales Sembrados]],"") | BE10: =IFERROR( Tabla14[[#This Row],[Animales según alimentación actual]]/(Tabla14[[#This Row],[Densidad/ha]]*Tabla14[[#This Row],[Ha]]),"")
A11: 710 | B11: MAX AP | C11: 8.71 | D11: 46170 | E11: 46178 | F11: =Tabla14[[#This Row],[Fecha]]-Tabla14[[#This Row],[Siembra]] -> 8 | G11: =IFERROR((((Tabla14[[#This Row],[Kg Alimento diario ]]-Tabla14[[#This Row],[Kg Alimento Sugerido]])/(Tabla14[[#This Row],[Kg Alimento Sugerido]])*100)),"") | H11: 6575 | I11: =IFERROR( IF(OFFSET(Tabla14[[#This Row],[Psc]],-1,0)=Tabla14[[#This Row],[Psc]], OFFSET(Tabla14[[#This Row],[Bal Acumulado]],-1,0)+Tabla14[[#This Row],[Kg/ semanal]], Tabla14[[#This Row],[Kg/ semanal]] ), Tabla14[[#This Row],[Kg/ semanal]] ) -> 6575 | J11: =IFERROR(((Tabla14[[#This Row],[Bal Acumulado]]*2.2046/Tabla14[[#This Row],[Ha]])/L11),"") -> 0.23959096 | K11: =Tabla14[[#This Row],[Animales vivos reportados]]*Tabla14[[#This Row],[Peso Actual]]/454/Tabla14[[#This Row],[Ha]] -> 6946.0352 | L11: =Tabla14[[#This Row],[Animales vivos reportados]]*Tabla14[[#This Row],[Peso Actual]]/454/Tabla14[[#This Row],[Ha]]+O9 -> 6946.0352 | O11: =Tabla14[[#This Row],[Raleo/total]]/Tabla14[[#This Row],[Ha]] -> 0 | P11: =IFERROR(Tabla14[[#This Row],[Kg Alimento diario ]]/Tabla14[[#This Row],[Ha]],"") -> 107.83992 | Q11: =IFERROR((Tabla14[[#This Row],[Kg Alimento diario ]])/(Tabla14[[#This Row],[Animales vivos reportados]]/100000),"") -> 40.69431 | R11: 7 | S11: =Tabla14[[#This Row],[Kg/ semanal]]/Tabla14[[#This Row],[Dias alimentados]] -> 939.28571 | T11: =Tabla14[[#This Row],[Kg Alimento Sugerido]]/Tabla14[[#This Row],[Ha]] -> 0 | W11: =Tabla14[[#This Row],[Kg Minimo]]/Tabla14[[#This Row],[Ha]] -> 0 | X11: 11.9 | Y11: =IFERROR(Tabla14[[#This Row],[Kg Alimento diario ]]/(Tabla14[[#This Row],[Peso Actual]]/1000*Tabla14[[#This Row],[Animales vivos reportados]]),"") -> 0.034196899 | Z11: =IFERROR(IF($Z$1="NormalCalor", VLOOKUP(Tabla14[[#This Row],[Peso Actual]], Tabla!$A$4:$C$76, 2, TRUE)/100, VLOOKUP(Tabla14[[#This Row],[Peso Actual]], Tabla!$A$4:$C$76, 3, TRUE)/100), "") -> 0.055 | AA11: =IFERROR(IF($AA$1="MinFrio",VLOOKUP(Tabla14[[#This Row],[Peso Actual]],Tabla!$F$3:$H$482,3,1),VLOOKUP(Tabla14[[#This Row],[Peso Actual]],Tabla!$F$3:$H$482,2,1)),"") -> 0.04723926 | AB11: =+Tabla14[[#This Row],[Biomasa de camaron ]]/Tabla14[[#This Row],[Ha]]*2.2 -> 0 | AC11: =U11/Z11 -> 0 | AD11: =V11/AA11 -> 0 | AE11: =+Tabla14[[#This Row],[Biomasa de Camaron bajo reportado]]*2.2 -> 60427.367 | AF11: =+(Tabla14[[#This Row],[Sobrevivencia total en finca]]/100)*Tabla14[[#This Row],[Animales vivos reportados]]*Tabla14[[#This Row],[Peso Actual]]/1000 -> 27466.985 | AG11: =+Tabla14[[#This Row],[Biomasa de camaron alimentacion actual]]/Tabla14[[#This Row],[Ha]]*2.2 -> 4313.5969 | AH11: =(Tabla14[[#This Row],[Kg Alimento diario ]]/Tabla14[[#This Row],[BW Sugerida]]) -> 17077.922 | AI11: =(Tabla14[[#This Row],[Kg Minimo]]/Tabla14[[#This Row],[BW(min)]]) -> 0 | AJ11: =Tabla14[[#This Row],[Densidad/ha]]*Tabla14[[#This Row],[Ha]] -> 2308150 | AK11: 265000 | AL11: =Tabla14[[#This Row],[Animales Sembrados]]*Tabla14[[#This Row],[Sobrevivencia total en finca]]/100 -> 2308150 | AM11: =Tabla14[[#This Row],[Animales vivos reportados]]*Tabla14[[#This Row],[Peso Actual]]/454/Tabla14[[#This Row],[Ha]] -> 6946.0352 | AN11: =IFERROR( (Tabla14[[#This Row],[Biomasa de camaron ]]*1000/Tabla14[[#This Row],[Peso Actual]]),"") -> 0 | AO11: =IFERROR(((Tabla14[[#This Row],[Biomasa de camaron alimentacion actual]]*1000)/Tabla14[[#This Row],[Peso Actual]]),"") -> 1435119.5 | AP11: =IFERROR( ( (Tabla14[[#This Row],[Biomasa de camaron alimentacion 2]]*1000)/Tabla14[[#This Row],[Peso Actual]]),"") -> 0 | AQ11: 22 | AR11: =IFERROR(Tabla14[[#This Row],[Animales vivos reportados]]/Tabla14[[#This Row],['#AA]],"") -> 104915.91 | AS11: =IFERROR(((Tabla14[[#This Row],[Lbs/ha sin Raleo]]*Tabla14[[#This Row],[Ha]])/Tabla14[[#This Row],['#AA]])/2.2046,"") -> 1247.3911 | AT11: 14 | AU11: 16 | AV11: 0.65 | AW11: =Tabla14[[#This Row],[Hp/AR]]*Tabla14[[#This Row],[%Efi AR]] -> 10.4 | AX11: =Tabla14[[#This Row],[Hp/Efi]]*Tabla14[[#This Row],['#AR]] -> 145.6 | AY11: =Tabla14[[#This Row],[Total hp/AR]]/Tabla14[[#This Row],[Ha]] -> 16.716418 | BB11: 100 | BC11: =IFERROR(Tabla14[[#This Row],[Animales vivos reportados]]/Tabla14[[#This Row],[Ha]]/10000,"") -> 26.5 | BD11: =IFERROR((Tabla14[[#This Row],[CXMT ACTUAL]]*10000*Tabla14[[#This Row],[Ha]])/Tabla14[[#This Row],[Animales Sembrados]],"") -> 1 | BE11: =IFERROR( Tabla14[[#This Row],[Animales según alimentación actual]]/(Tabla14[[#This Row],[Densidad/ha]]*Tabla14[[#This Row],[Ha]]),"") -> 0.6217618
A12: 710 | B12: MAX AP | C12: 8.71 | D12: 46170 | E12: =E11+7 -> 46185 | F12: =Tabla14[[#This Row],[Fecha]]-Tabla14[[#This Row],[Siembra]] -> 15 | G12: =IFERROR((((Tabla14[[#This Row],[Kg Alimento diario ]]-Tabla14[[#This Row],[Kg Alimento Sugerido]])/(Tabla14[[#This Row],[Kg Alimento Sugerido]])*100)),"") | H12: 5700 | I12: =IFERROR( IF(OFFSET(Tabla14[[#This Row],[Psc]],-1,0)=Tabla14[[#This Row],[Psc]], OFFSET(Tabla14[[#This Row],[Bal Acumulado]],-1,0)+Tabla14[[#This Row],[Kg/ semanal]], Tabla14[[#This Row],[Kg/ semanal]] ), Tabla14[[#This Row],[Kg/ semanal]] ) -> 12275 | J12: =IFERROR(((Tabla14[[#This Row],[Bal Acumulado]]*2.2046/Tabla14[[#This Row],[Ha]])/L12),"") -> 0.35965112 | K12: =Tabla14[[#This Row],[Animales vivos reportados]]*Tabla14[[#This Row],[Peso Actual]]/454/Tabla14[[#This Row],[Ha]] -> 8638.7665 | L12: =Tabla14[[#This Row],[Animales vivos reportados]]*Tabla14[[#This Row],[Peso Actual]]/454/Tabla14[[#This Row],[Ha]]+O10 -> 8638.7665 | O12: =Tabla14[[#This Row],[Raleo/total]]/Tabla14[[#This Row],[Ha]] -> 0 | P12: =IFERROR(Tabla14[[#This Row],[Kg Alimento diario ]]/Tabla14[[#This Row],[Ha]],"") -> 93.488601 | Q12: =IFERROR((Tabla14[[#This Row],[Kg Alimento diario ]])/(Tabla14[[#This Row],[Animales vivos reportados]]/100000),"") -> 35.278717 | R12: 7 | S12: =Tabla14[[#This Row],[Kg/ semanal]]/Tabla14[[#This Row],[Dias alimentados]] -> 814.28571 | T12: =Tabla14[[#This Row],[Kg Alimento Sugerido]]/Tabla14[[#This Row],[Ha]] -> 0 | W12: =Tabla14[[#This Row],[Kg Minimo]]/Tabla14[[#This Row],[Ha]] -> 0 | X12: 14.8 | Y12: =IFERROR(Tabla14[[#This Row],[Kg Alimento diario ]]/(Tabla14[[#This Row],[Peso Actual]]/1000*Tabla14[[#This Row],[Animales vivos reportados]]),"") -> 0.023836971 | Z12: =IFERROR(IF($Z$1="NormalCalor", VLOOKUP(Tabla14[[#This Row],[Peso Actual]], Tabla!$A$4:$C$76, 2, TRUE)/100, VLOOKUP(Tabla14[[#This Row],[Peso Actual]], Tabla!$A$4:$C$76, 3, TRUE)/100), "") -> 0.049 | AA12: =IFERROR(IF($AA$1="MinFrio",VLOOKUP(Tabla14[[#This Row],[Peso Actual]],Tabla!$F$3:$H$482,3,1),VLOOKUP(Tabla14[[#This Row],[Peso Actual]],Tabla!$F$3:$H$482,2,1)),"") -> 0.043026269 | AB12: =+Tabla14[[#This Row],[Biomasa de camaron ]]/Tabla14[[#This Row],[Ha]]*2.2 -> 0 | AC12: =U12/Z12 -> 0 | AD12: =V12/AA12 -> 0 | AE12: =+Tabla14[[#This Row],[Biomasa de Camaron bajo reportado]]*2.2 -> 75153.364 | AF12: =+(Tabla14[[#This Row],[Sobrevivencia total en finca]]/100)*Tabla14[[#This Row],[Animales vivos reportados]]*Tabla14[[#This Row],[Peso Actual]]/1000 -> 34160.62 | AG12: =+Tabla14[[#This Row],[Biomasa de camaron alimentacion actual]]/Tabla14[[#This Row],[Ha]]*2.2 -> 4197.4474 | AH12: =(Tabla14[[#This Row],[Kg Alimento diario ]]/Tabla14[[#This Row],[BW Sugerida]]) -> 16618.076 | AI12: =(Tabla14[[#This Row],[Kg Minimo]]/Tabla14[[#This Row],[BW(min)]]) -> 0 | AJ12: =Tabla14[[#This Row],[Densidad/ha]]*Tabla14[[#This Row],[Ha]] -> 2308150 | AK12: 265000 | AL12: =Tabla14[[#This Row],[Animales Sembrados]]*Tabla14[[#This Row],[Sobrevivencia total en finca]]/100 -> 2308150 | AM12: =Tabla14[[#This Row],[Animales vivos reportados]]*Tabla14[[#This Row],[Peso Actual]]/454/Tabla14[[#This Row],[Ha]] -> 8638.7665 | AN12: =IFERROR( (Tabla14[[#This Row],[Biomasa de camaron ]]*1000/Tabla14[[#This Row],[Peso Actual]]),"") -> 0 | AO12: =IFERROR(((Tabla14[[#This Row],[Biomasa de camaron alimentacion actual]]*1000)/Tabla14[[#This Row],[Peso Actual]]),"") -> 1122843 | AP12: =IFERROR( ( (Tabla14[[#This Row],[Biomasa de camaron alimentacion 2]]*1000)/Tabla14[[#This Row],[Peso Actual]]),"") -> 0 | AQ12: 22 | AR12: =IFERROR(Tabla14[[#This Row],[Animales vivos reportados]]/Tabla14[[#This Row],['#AA]],"") -> 104915.91 | AS12: =IFERROR(((Tabla14[[#This Row],[Lbs/ha sin Raleo]]*Tabla14[[#This Row],[Ha]])/Tabla14[[#This Row],['#AA]])/2.2046,"") -> 1551.3772 | AT12: 14 | AU12: 16 | AV12: 0.65 | AW12: =Tabla14[[#This Row],[Hp/AR]]*Tabla14[[#This Row],[%Efi AR]] -> 10.4 | AX12: =Tabla14[[#This Row],[Hp/Efi]]*Tabla14[[#This Row],['#AR]] -> 145.6 | AY12: =Tabla14[[#This Row],[Total hp/AR]]/Tabla14[[#This Row],[Ha]] -> 16.716418 | AZ12: =IF(Tabla14[[#This Row],[Peso Actual]]>X11,Tabla14[[#This Row],[Peso Actual]]-X11,"") -> 2.9 | BB12: 100 | BC12: =IFERROR(Tabla14[[#This Row],[Animales vivos reportados]]/Tabla14[[#This Row],[Ha]]/10000,"") -> 26.5 | BD12: =IFERROR((Tabla14[[#This Row],[CXMT ACTUAL]]*10000*Tabla14[[#This Row],[Ha]])/Tabla14[[#This Row],[Animales Sembrados]],"") -> 1 | BE12: =IFERROR( Tabla14[[#This Row],[Animales según alimentación actual]]/(Tabla14[[#This Row],[Densidad/ha]]*Tabla14[[#This Row],[Ha]]),"") -> 0.4864688
A13: 710 | B13: MAX AP | C13: 8.71 | D13: 46170 | E13: =E12+7 -> 46192 | F13: =Tabla14[[#This Row],[Fecha]]-Tabla14[[#This Row],[Siembra]] -> 22 | G13: =IFERROR((((Tabla14[[#This Row],[Kg Alimento diario ]]-Tabla14[[#This Row],[Kg Alimento Sugerido]])/(Tabla14[[#This Row],[Kg Alimento Sugerido]])*100)),"") | I13: =IFERROR( IF(OFFSET(Tabla14[[#This Row],[Psc]],-1,0)=Tabla14[[#This Row],[Psc]], OFFSET(Tabla14[[#This Row],[Bal Acumulado]],-1,0)+Tabla14[[#This Row],[Kg/ semanal]], Tabla14[[#This Row],[Kg/ semanal]] ), Tabla14[[#This Row],[Kg/ semanal]] ) -> 12275 | J13: =IFERROR(((Tabla14[[#This Row],[Bal Acumulado]]*2.2046/Tabla14[[#This Row],[Ha]])/L13),"") | K13: =Tabla14[[#This Row],[Animales vivos reportados]]*Tabla14[[#This Row],[Peso Actual]]/454/Tabla14[[#This Row],[Ha]] -> 0 | L13: =Tabla14[[#This Row],[Animales vivos reportados]]*Tabla14[[#This Row],[Peso Actual]]/454/Tabla14[[#This Row],[Ha]]+O11 -> 0 | O13: =Tabla14[[#This Row],[Raleo/total]]/Tabla14[[#This Row],[Ha]] -> 0 | P13: =IFERROR(Tabla14[[#This Row],[Kg Alimento diario ]]/Tabla14[[#This Row],[Ha]],"") -> 0 | Q13: =IFERROR((Tabla14[[#This Row],[Kg Alimento diario ]])/(Tabla14[[#This Row],[Animales vivos reportados]]/100000),"") -> 0 | R13: 7 | S13: =Tabla14[[#This Row],[Kg/ semanal]]/Tabla14[[#This Row],[Dias alimentados]] -> 0 | T13: =Tabla14[[#This Row],[Kg Alimento Sugerido]]/Tabla14[[#This Row],[Ha]] -> 0 | W13: =Tabla14[[#This Row],[Kg Minimo]]/Tabla14[[#This Row],[Ha]] -> 0 | Y13: =IFERROR(Tabla14[[#This Row],[Kg Alimento diario ]]/(Tabla14[[#This Row],[Peso Actual]]/1000*Tabla14[[#This Row],[Animales vivos reportados]]),"") | Z13: =IFERROR(IF($Z$1="NormalCalor", VLOOKUP(Tabla14[[#This Row],[Peso Actual]], Tabla!$A$4:$C$76, 2, TRUE)/100, VLOOKUP(Tabla14[[#This Row],[Peso Actual]], Tabla!$A$4:$C$76, 3, TRUE)/100), "") | AA13: =IFERROR(IF($AA$1="MinFrio",VLOOKUP(Tabla14[[#This Row],[Peso Actual]],Tabla!$F$3:$H$482,3,1),VLOOKUP(Tabla14[[#This Row],[Peso Actual]],Tabla!$F$3:$H$482,2,1)),"") | AB13: =+Tabla14[[#This Row],[Biomasa de camaron ]]/Tabla14[[#This Row],[Ha]]*2.2 -> #VALUE! | AC13: =U13/Z13 -> #VALUE! | AD13: =V13/AA13 -> #VALUE! | AE13: =+Tabla14[[#This Row],[Biomasa de Camaron bajo reportado]]*2.2 -> 0 | AF13: =+(Tabla14[[#This Row],[Sobrevivencia total en finca]]/100)*Tabla14[[#This Row],[Animales vivos reportados]]*Tabla14[[#This Row],[Peso Actual]]/1000 -> 0 | AG13: =+Tabla14[[#This Row],[Biomasa de camaron alimentacion actual]]/Tabla14[[#This Row],[Ha]]*2.2 -> #VALUE! | AH13: =(Tabla14[[#This Row],[Kg Alimento diario ]]/Tabla14[[#This Row],[BW Sugerida]]) -> #VALUE! | AI13: =(Tabla14[[#This Row],[Kg Minimo]]/Tabla14[[#This Row],[BW(min)]]) -> #VALUE! | AJ13: =Tabla14[[#This Row],[Densidad/ha]]*Tabla14[[#This Row],[Ha]] -> 2308150 | AK13: 265000 | AL13: =Tabla14[[#This Row],[Animales Sembrados]]*Tabla14[[#This Row],[Sobrevivencia total en finca]]/100 -> 2308150 | AM13: =Tabla14[[#This Row],[Animales vivos reportados]]*Tabla14[[#This Row],[Peso Actual]]/454/Tabla14[[#This Row],[Ha]] -> 0 | AN13: =IFERROR( (Tabla14[[#This Row],[Biomasa de camaron ]]*1000/Tabla14[[#This Row],[Peso Actual]]),"") | AO13: =IFERROR(((Tabla14[[#This Row],[Biomasa de camaron alimentacion actual]]*1000)/Tabla14[[#This Row],[Peso Actual]]),"") | AP13: =IFERROR( ( (Tabla14[[#This Row],[Biomasa de camaron alimentacion 2]]*1000)/Tabla14[[#This Row],[Peso Actual]]),"") | AQ13: 22 | AR13: =IFERROR(Tabla14[[#This Row],[Animales vivos reportados]]/Tabla14[[#This Row],['#AA]],"") -> 104915.91 | AS13: =IFERROR(((Tabla14[[#This Row],[Lbs/ha sin Raleo]]*Tabla14[[#This Row],[Ha]])/Tabla14[[#This Row],['#AA]])/2.2046,"") -> 0 | AT13: 14 | AU13: 16 | AV13: 0.65 | AW13: =Tabla14[[#This Row],[Hp/AR]]*Tabla14[[#This Row],[%Efi AR]] -> 10.4 | AX13: =Tabla14[[#This Row],[Hp/Efi]]*Tabla14[[#This Row],['#AR]] -> 145.6 | AY13: =Tabla14[[#This Row],[Total hp/AR]]/Tabla14[[#This Row],[Ha]] -> 16.716418 | BB13: 100 | BC13: =IFERROR(Tabla14[[#This Row],[Animales vivos reportados]]/Tabla14[[#This Row],[Ha]]/10000,"") -> 26.5 | BD13: =IFERROR((Tabla14[[#This Row],[CXMT ACTUAL]]*10000*Tabla14[[#This Row],[Ha]])/Tabla14[[#This Row],[Animales Sembrados]],"") -> 1 | BE13: =IFERROR( Tabla14[[#This Row],[Animales según alimentación actual]]/(Tabla14[[#This Row],[Densidad/ha]]*Tabla14[[#This Row],[Ha]]),"")
A14: 710 | B14: MAX AP | C14: 8.71 | D14: 46170 | E14: =E13+7 -> 46199 | F14: =Tabla14[[#This Row],[Fecha]]-Tabla14[[#This Row],[Siembra]] -> 29 | G14: =IFERROR((((Tabla14[[#This Row],[Kg Alimento diario ]]-Tabla14[[#This Row],[Kg Alimento Sugerido]])/(Tabla14[[#This Row],[Kg Alimento Sugerido]])*100)),"") | I14: =IFERROR( IF(OFFSET(Tabla14[[#This Row],[Psc]],-1,0)=Tabla14[[#This Row],[Psc]], OFFSET(Tabla14[[#This Row],[Bal Acumulado]],-1,0)+Tabla14[[#This Row],[Kg/ semanal]], Tabla14[[#This Row],[Kg/ semanal]] ), Tabla14[[#This Row],[Kg/ semanal]] ) -> 12275 | J14: =IFERROR(((Tabla14[[#This Row],[Bal Acumulado]]*2.2046/Tabla14[[#This Row],[Ha]])/L14),"") | K14: =Tabla14[[#This Row],[Animales vivos reportados]]*Tabla14[[#This Row],[Peso Actual]]/454/Tabla14[[#This Row],[Ha]] -> 0 | L14: =Tabla14[[#This Row],[Animales vivos reportados]]*Tabla14[[#This Row],[Peso Actual]]/454/Tabla14[[#This Row],[Ha]]+O12 -> 0 | O14: =Tabla14[[#This Row],[Raleo/total]]/Tabla14[[#This Row],[Ha]] -> 0 | P14: =IFERROR(Tabla14[[#This Row],[Kg Alimento diario ]]/Tabla14[[#This Row],[Ha]],"") -> 0 | Q14: =IFERROR((Tabla14[[#This Row],[Kg Alimento diario ]])/(Tabla14[[#This Row],[Animales vivos reportados]]/100000),"") -> 0 | R14: 7 | S14: =Tabla14[[#This Row],[Kg/ semanal]]/Tabla14[[#This Row],[Dias alimentados]] -> 0 | T14: =Tabla14[[#This Row],[Kg Alimento Sugerido]]/Tabla14[[#This Row],[Ha]] -> 0 | W14: =Tabla14[[#This Row],[Kg Minimo]]/Tabla14[[#This Row],[Ha]] -> 0 | Y14: =IFERROR(Tabla14[[#This Row],[Kg Alimento diario ]]/(Tabla14[[#This Row],[Peso Actual]]/1000*Tabla14[[#This Row],[Animales vivos reportados]]),"") | Z14: =IFERROR(IF($Z$1="NormalCalor", VLOOKUP(Tabla14[[#This Row],[Peso Actual]], Tabla!$A$4:$C$76, 2, TRUE)/100, VLOOKUP(Tabla14[[#This Row],[Peso Actual]], Tabla!$A$4:$C$76, 3, TRUE)/100), "") | AA14: =IFERROR(IF($AA$1="MinFrio",VLOOKUP(Tabla14[[#This Row],[Peso Actual]],Tabla!$F$3:$H$482,3,1),VLOOKUP(Tabla14[[#This Row],[Peso Actual]],Tabla!$F$3:$H$482,2,1)),"") | AB14: =+Tabla14[[#This Row],[Biomasa de camaron ]]/Tabla14[[#This Row],[Ha]]*2.2 -> #VALUE! | AC14: =U14/Z14 -> #VALUE! | AD14: =V14/AA14 -> #VALUE! | AE14: =+Tabla14[[#This Row],[Biomasa de Camaron bajo reportado]]*2.2 -> 0 | AF14: =+(Tabla14[[#This Row],[Sobrevivencia total en finca]]/100)*Tabla14[[#This Row],[Animales vivos reportados]]*Tabla14[[#This Row],[Peso Actual]]/1000 -> 0 | AG14: =+Tabla14[[#This Row],[Biomasa de camaron alimentacion actual]]/Tabla14[[#This Row],[Ha]]*2.2 -> #VALUE! | AH14: =(Tabla14[[#This Row],[Kg Alimento diario ]]/Tabla14[[#This Row],[BW Sugerida]]) -> #VALUE! | AI14: =(Tabla14[[#This Row],[Kg Minimo]]/Tabla14[[#This Row],[BW(min)]]) -> #VALUE! | AJ14: =Tabla14[[#This Row],[Densidad/ha]]*Tabla14[[#This Row],[Ha]] -> 2308150 | AK14: 265000 | AL14: =Tabla14[[#This Row],[Animales Sembrados]]*Tabla14[[#This Row],[Sobrevivencia total en finca]]/100 -> 2308150 | AM14: =Tabla14[[#This Row],[Animales vivos reportados]]*Tabla14[[#This Row],[Peso Actual]]/454/Tabla14[[#This Row],[Ha]] -> 0 | AN14: =IFERROR( (Tabla14[[#This Row],[Biomasa de camaron ]]*1000/Tabla14[[#This Row],[Peso Actual]]),"") | AO14: =IFERROR(((Tabla14[[#This Row],[Biomasa de camaron alimentacion actual]]*1000)/Tabla14[[#This Row],[Peso Actual]]),"") | AP14: =IFERROR( ( (Tabla14[[#This Row],[Biomasa de camaron alimentacion 2]]*1000)/Tabla14[[#This Row],[Peso Actual]]),"") | AQ14: 22 | AR14: =IFERROR(Tabla14[[#This Row],[Animales vivos reportados]]/Tabla14[[#This Row],['#AA]],"") -> 104915.91 | AS14: =IFERROR(((Tabla14[[#This Row],[Lbs/ha sin Raleo]]*Tabla14[[#This Row],[Ha]])/Tabla14[[#This Row],['#AA]])/2.2046,"") -> 0 | AT14: 14 | AU14: 16 | AV14: 0.65 | AW14: =Tabla14[[#This Row],[Hp/AR]]*Tabla14[[#This Row],[%Efi AR]] -> 10.4 | AX14: =Tabla14[[#This Row],[Hp/Efi]]*Tabla14[[#This Row],['#AR]] -> 145.6 | AY14: =Tabla14[[#This Row],[Total hp/AR]]/Tabla14[[#This Row],[Ha]] -> 16.716418 | BB14: 100 | BC14: =IFERROR(Tabla14[[#This Row],[Animales vivos reportados]]/Tabla14[[#This Row],[Ha]]/10000,"") -> 26.5 | BD14: =IFERROR((Tabla14[[#This Row],[CXMT ACTUAL]]*10000*Tabla14[[#This Row],[Ha]])/Tabla14[[#This Row],[Animales Sembrados]],"") -> 1 | BE14: =IFERROR( Tabla14[[#This Row],[Animales según alimentación actual]]/(Tabla14[[#This Row],[Densidad/ha]]*Tabla14[[#This Row],[Ha]]),"")
A15: 710 | B15: MAX AP | C15: 8.71 | D15: 46170 | E15: =E14+7 -> 46206 | F15: =Tabla14[[#This Row],[Fecha]]-Tabla14[[#This Row],[Siembra]] -> 36 | G15: =IFERROR((((Tabla14[[#This Row],[Kg Alimento diario ]]-Tabla14[[#This Row],[Kg Alimento Sugerido]])/(Tabla14[[#This Row],[Kg Alimento Sugerido]])*100)),"") | I15: =IFERROR( IF(OFFSET(Tabla14[[#This Row],[Psc]],-1,0)=Tabla14[[#This Row],[Psc]], OFFSET(Tabla14[[#This Row],[Bal Acumulado]],-1,0)+Tabla14[[#This Row],[Kg/ semanal]], Tabla14[[#This Row],[Kg/ semanal]] ), Tabla14[[#This Row],[Kg/ semanal]] ) -> 12275 | J15: =IFERROR(((Tabla14[[#This Row],[Bal Acumulado]]*2.2046/Tabla14[[#This Row],[Ha]])/L15),"") | K15: =Tabla14[[#This Row],[Animales vivos reportados]]*Tabla14[[#This Row],[Peso Actual]]/454/Tabla14[[#This Row],[Ha]] -> 0 | L15: =Tabla14[[#This Row],[Animales vivos reportados]]*Tabla14[[#This Row],[Peso Actual]]/454/Tabla14[[#This Row],[Ha]]+O13 -> 0 | O15: =Tabla14[[#This Row],[Raleo/total]]/Tabla14[[#This Row],[Ha]] -> 0 | P15: =IFERROR(Tabla14[[#This Row],[Kg Alimento diario ]]/Tabla14[[#This Row],[Ha]],"") -> 0 | Q15: =IFERROR((Tabla14[[#This Row],[Kg Alimento diario ]])/(Tabla14[[#This Row],[Animales vivos reportados]]/100000),"") -> 0 | R15: 7 | S15: =Tabla14[[#This Row],[Kg/ semanal]]/Tabla14[[#This Row],[Dias alimentados]] -> 0 | T15: =Tabla14[[#This Row],[Kg Alimento Sugerido]]/Tabla14[[#This Row],[Ha]] -> 0 | W15: =Tabla14[[#This Row],[Kg Minimo]]/Tabla14[[#This Row],[Ha]] -> 0 | Y15: =IFERROR(Tabla14[[#This Row],[Kg Alimento diario ]]/(Tabla14[[#This Row],[Peso Actual]]/1000*Tabla14[[#This Row],[Animales vivos reportados]]),"") | Z15: =IFERROR(IF($Z$1="NormalCalor", VLOOKUP(Tabla14[[#This Row],[Peso Actual]], Tabla!$A$4:$C$76, 2, TRUE)/100, VLOOKUP(Tabla14[[#This Row],[Peso Actual]], Tabla!$A$4:$C$76, 3, TRUE)/100), "") | AA15: =IFERROR(IF($AA$1="MinFrio",VLOOKUP(Tabla14[[#This Row],[Peso Actual]],Tabla!$F$3:$H$482,3,1),VLOOKUP(Tabla14[[#This Row],[Peso Actual]],Tabla!$F$3:$H$482,2,1)),"") | AB15: =+Tabla14[[#This Row],[Biomasa de camaron ]]/Tabla14[[#This Row],[Ha]]*2.2 -> #VALUE! | AC15: =U15/Z15 -> #VALUE! | AD15: =V15/AA15 -> #VALUE! | AE15: =+Tabla14[[#This Row],[Biomasa de Camaron bajo reportado]]*2.2 -> 0 | AF15: =+(Tabla14[[#This Row],[Sobrevivencia total en finca]]/100)*Tabla14[[#This Row],[Animales vivos reportados]]*Tabla14[[#This Row],[Peso Actual]]/1000 -> 0 | AG15: =+Tabla14[[#This Row],[Biomasa de camaron alimentacion actual]]/Tabla14[[#This Row],[Ha]]*2.2 -> #VALUE! | AH15: =(Tabla14[[#This Row],[Kg Alimento diario ]]/Tabla14[[#This Row],[BW Sugerida]]) -> #VALUE! | AI15: =(Tabla14[[#This Row],[Kg Minimo]]/Tabla14[[#This Row],[BW(min)]]) -> #VALUE! | AJ15: =Tabla14[[#This Row],[Densidad/ha]]*Tabla14[[#This Row],[Ha]] -> 2308150 | AK15: 265000 | AL15: =Tabla14[[#This Row],[Animales Sembrados]]*Tabla14[[#This Row],[Sobrevivencia total en finca]]/100 -> 2308150 | AM15: =Tabla14[[#This Row],[Animales vivos reportados]]*Tabla14[[#This Row],[Peso Actual]]/454/Tabla14[[#This Row],[Ha]] -> 0 | AN15: =IFERROR( (Tabla14[[#This Row],[Biomasa de camaron ]]*1000/Tabla14[[#This Row],[Peso Actual]]),"") | AO15: =IFERROR(((Tabla14[[#This Row],[Biomasa de camaron alimentacion actual]]*1000)/Tabla14[[#This Row],[Peso Actual]]),"") | AP15: =IFERROR( ( (Tabla14[[#This Row],[Biomasa de camaron alimentacion 2]]*1000)/Tabla14[[#This Row],[Peso Actual]]),"") | AQ15: 22 | AR15: =IFERROR(Tabla14[[#This Row],[Animales vivos reportados]]/Tabla14[[#This Row],['#AA]],"") -> 104915.91 | AS15: =IFERROR(((Tabla14[[#This Row],[Lbs/ha sin Raleo]]*Tabla14[[#This Row],[Ha]])/Tabla14[[#This Row],['#AA]])/2.2046,"") -> 0 | AT15: 14 | AU15: 16 | AV15: 0.65 | AW15: =Tabla14[[#This Row],[Hp/AR]]*Tabla14[[#This Row],[%Efi AR]] -> 10.4 | AX15: =Tabla14[[#This Row],[Hp/Efi]]*Tabla14[[#This Row],['#AR]] -> 145.6 | AY15: =Tabla14[[#This Row],[Total hp/AR]]/Tabla14[[#This Row],[Ha]] -> 16.716418 | BB15: 100 | BC15: =IFERROR(Tabla14[[#This Row],[Animales vivos reportados]]/Tabla14[[#This Row],[Ha]]/10000,"") -> 26.5 | BD15: =IFERROR((Tabla14[[#This Row],[CXMT ACTUAL]]*10000*Tabla14[[#This Row],[Ha]])/Tabla14[[#This Row],[Animales Sembrados]],"") -> 1 | BE15: =IFERROR( Tabla14[[#This Row],[Animales según alimentación actual]]/(Tabla14[[#This Row],[Densidad/ha]]*Tabla14[[#This Row],[Ha]]),"")
